<?xml version="1.0"?>
<robot name="nuc_bot">

  <material name="blue">
    <color rgba="0 0 0.8 1"/>
  </material>

  <material name="white">
    <color rgba="1 1 1 1"/>
  </material>

  <material name="black">
    <color rgba="0 0 0 1"/>
  </material>

  <material name="silver">
    <color rgba=".75 .75 .75 1"/>
  </material>
  
  <link name="base_link">
    <visual>
      <geometry>
        <box size=".190 .190 .095"/>
      </geometry>
      <material name="black"/>
    </visual>
    <collision>
      <geometry>
        <box size=".190 .190 .095"/>
      </geometry>
    </collision>
    <inertial>
      <mass value="1.0"/>
      <inertia ixx="0.015" iyy="0.0375" izz="0.0375"
                ixy="0" ixz="0" iyz="0"/>
    </inertial>
  </link>

  <link name="front_caster">
    <visual>
      <geometry>
        <box size=".0275 .0275 .0275"/>
      </geometry>
      <material name="silver"/>
    </visual>
    <collision>
      <geometry>
        <box size=".0275 .0275 .0275"/>
      </geometry>
    </collision>
    <inertial>
      <mass value=".1"/>
      <inertia ixx="0.00083" iyy="0.00083" izz="0.000167"
                ixy="0" ixz="0" iyz="0"/>
    </inertial>
  </link>

  <link name="front_wheel">
    <visual>
      <geometry>
        <cylinder length=".0275" radius=".0275"/>
      </geometry>
      <material name="black"/>
    </visual>
    <collision>
      <geometry>
        <cylinder length=".0275" radius=".0275"/>
      </geometry>
    </collision>
    <inertial>
      <mass value=".1"/>
      <inertia ixx="5.1458e-5" iyy="5.1458e-5" izz="6.125e-5"
                ixy="0" ixz="0" iyz="0"/>
    </inertial>
  </link>
  

  <link name="rear_caster">
    <visual>
      <geometry>
        <box size=".0275 .0275 .0275"/>
      </geometry>
      <material name="silver"/>
    </visual>
    <collision>
      <geometry>
        <box size=".0275 .0275 .0275"/>
      </geometry>
    </collision>
    <inertial>
      <mass value=".1"/>
      <inertia ixx="0.00083" iyy="0.00083" izz="0.000167"
                ixy="0" ixz="0" iyz="0"/>
    </inertial>
  </link>

  <link name="rear_wheel">
    <visual>
      <geometry>
        <cylinder length=".0275" radius=".0275"/>
      </geometry>
      <material name="black"/>
    </visual>
    <collision>
      <geometry>
        <cylinder length=".0275" radius=".0275"/>
      </geometry>
    </collision>
    <inertial>
      <mass value=".1"/>
      <inertia ixx="5.1458e-5" iyy="5.1458e-5" izz="6.125e-5"
                ixy="0" ixz="0" iyz="0"/>
    </inertial>
  </link>
  
  <link name="laser">
    <visual>
      <geometry>
        <cylinder length=".040" radius=".035"/>
      </geometry>
      <material name="white"/>
    </visual>
    <collision>
      <geometry>
        <cylinder length=".040" radius=".035"/>
      </geometry>
    </collision>
  </link>

  <link name="right_wheel">
    <visual>
      <geometry>
        <cylinder length=".010" radius=".045"/>
      </geometry>
      <material name="white"/>
    </visual>
    <collision>
      <geometry>
        <cylinder length=".010" radius=".045"/>
      </geometry>
    </collision>
    <inertial>
      <mass value=".1"/>
      <inertia ixx="5.1458e-5" iyy="5.1458e-5" izz="6.125e-5"
                ixy="0" ixz="0" iyz="0"/>
    </inertial>
  </link>

  <link name="left_wheel">
    <visual>
      <geometry>
        <cylinder length=".010" radius=".045"/>
      </geometry>
      <material name="white"/>
    </visual>
    <collision>
      <geometry>
        <cylinder length=".010" radius=".045"/>
      </geometry>
    </collision>
    <inertial>
      <mass value=".1"/>
      <inertia ixx="5.1458e-5" iyy="5.1458e-5" izz="6.125e-5"
                ixy="0" ixz="0" iyz="0"/>
    </inertial>
  </link>

  <joint name="right_wheel_joint" type="continuous">
    <axis xyz="0 0 1"/>
    <parent link="base_link"/>
    <child link="right_wheel"/>
    <origin rpy="1.5708 0 0" xyz="0 -.1 -.055"/>
  </joint>

  <joint name="left_wheel_joint" type="continuous">
    <axis xyz="0 0 1"/>
    <parent link="base_link"/>
    <child link="left_wheel"/>
    <origin rpy="-1.5708 0 0" xyz="0 .1 -.055"/>
  </joint>

  <joint name="front_caster_joint" type="continuous">
    <axis xyz="0 0 1"/>
    <parent link="base_link"/>
    <child link="front_caster"/>
    <origin rpy="0 0 0" xyz=".095 0 -.06125"/>
  </joint>

  <joint name="front_wheel_joint" type="continuous">
    <axis xyz="0 0 1"/>
    <parent link="front_caster"/>
    <child link="front_wheel"/>
    <origin rpy="-1.5708 0 0" xyz="0 0 -0.01375"/>
  </joint>

  <joint name="rear_caster_joint" type="continuous">
    <axis xyz="0 0 1"/>
    <parent link="base_link"/>
    <child link="rear_caster"/>
    <origin rpy="0 0 0" xyz="-.095 0 -.06125"/>
  </joint>

  <joint name="rear_wheel_joint" type="continuous">
    <axis xyz="0 0 1"/>
    <parent link="rear_caster"/>
    <child link="rear_wheel"/>
    <origin rpy="-1.5708 0 0" xyz="0 0 -0.01375"/>
  </joint>
 
  <joint name="robot_body_to_laser" type="continuous">
    <axis xyz="0 0 1"/>
    <parent link="base_link"/>
    <child link="laser"/>
    <origin rpy="0 0 0" xyz="0 0 .0675"/>
  </joint>

  
</robot>
